[2024-11-03T04:09:00.929+0000] {local_task_job_runner.py:123} INFO - ::group::Pre task execution logs
[2024-11-03T04:09:00.937+0000] {taskinstance.py:2612} INFO - Dependencies all met for dep_context=non-requeueable deps ti=<TaskInstance: load_sales_data_to_db.fetch_sales_data_raw scheduled__2024-11-03T04:08:00+00:00 [queued]>
[2024-11-03T04:09:00.942+0000] {taskinstance.py:2612} INFO - Dependencies all met for dep_context=requeueable deps ti=<TaskInstance: load_sales_data_to_db.fetch_sales_data_raw scheduled__2024-11-03T04:08:00+00:00 [queued]>
[2024-11-03T04:09:00.942+0000] {taskinstance.py:2865} INFO - Starting attempt 1 of 2
[2024-11-03T04:09:00.948+0000] {taskinstance.py:2888} INFO - Executing <Task(PythonOperator): fetch_sales_data_raw> on 2024-11-03 04:08:00+00:00
[2024-11-03T04:09:00.951+0000] {warnings.py:112} WARNING - /home/***/.local/lib/python3.12/site-packages/***/task/task_runner/standard_task_runner.py:70: DeprecationWarning: This process (pid=446) is multi-threaded, use of fork() may lead to deadlocks in the child.
  pid = os.fork()

[2024-11-03T04:09:00.952+0000] {standard_task_runner.py:72} INFO - Started process 451 to run task
[2024-11-03T04:09:00.953+0000] {standard_task_runner.py:104} INFO - Running: ['***', 'tasks', 'run', 'load_sales_data_to_db', 'fetch_sales_data_raw', 'scheduled__2024-11-03T04:08:00+00:00', '--job-id', '190', '--raw', '--subdir', 'DAGS_FOLDER/raw/dag_load_sales_data_to_db.py', '--cfg-path', '/tmp/tmpv9o750wz']
[2024-11-03T04:09:00.954+0000] {standard_task_runner.py:105} INFO - Job 190: Subtask fetch_sales_data_raw
[2024-11-03T04:09:00.985+0000] {task_command.py:467} INFO - Running <TaskInstance: load_sales_data_to_db.fetch_sales_data_raw scheduled__2024-11-03T04:08:00+00:00 [running]> on host d6ae48c81f92
[2024-11-03T04:09:01.024+0000] {taskinstance.py:3131} INFO - Exporting env vars: AIRFLOW_CTX_DAG_OWNER='***' AIRFLOW_CTX_DAG_ID='load_sales_data_to_db' AIRFLOW_CTX_TASK_ID='fetch_sales_data_raw' AIRFLOW_CTX_EXECUTION_DATE='2024-11-03T04:08:00+00:00' AIRFLOW_CTX_TRY_NUMBER='1' AIRFLOW_CTX_DAG_RUN_ID='scheduled__2024-11-03T04:08:00+00:00'
[2024-11-03T04:09:01.025+0000] {logging_mixin.py:190} INFO - Task instance is in running state
[2024-11-03T04:09:01.025+0000] {logging_mixin.py:190} INFO -  Previous state of the Task instance: queued
[2024-11-03T04:09:01.025+0000] {logging_mixin.py:190} INFO - Current task name:fetch_sales_data_raw state:running start_date:2024-11-03 04:09:00.937735+00:00
[2024-11-03T04:09:01.026+0000] {logging_mixin.py:190} INFO - Dag name:load_sales_data_to_db and current dag run status:running
[2024-11-03T04:09:01.026+0000] {taskinstance.py:731} INFO - ::endgroup::
[2024-11-03T04:09:01.964+0000] {raw_fetch_sales_api.py:31} ERROR - Failed to fetch data from API: Error fetching data, status code: 404
[2024-11-03T04:09:01.964+0000] {taskinstance.py:3310} ERROR - Task failed with exception
Traceback (most recent call last):
  File "/home/airflow/.local/lib/python3.12/site-packages/airflow/models/taskinstance.py", line 767, in _execute_task
    result = _execute_callable(context=context, **execute_callable_kwargs)
             ^^^^^^^^^^^^^^^^^^^^^^^^^^^^^^^^^^^^^^^^^^^^^^^^^^^^^^^^^^^^^
  File "/home/airflow/.local/lib/python3.12/site-packages/airflow/models/taskinstance.py", line 733, in _execute_callable
    return ExecutionCallableRunner(
           ^^^^^^^^^^^^^^^^^^^^^^^^
  File "/home/airflow/.local/lib/python3.12/site-packages/airflow/utils/operator_helpers.py", line 252, in run
    return self.func(*args, **kwargs)
           ^^^^^^^^^^^^^^^^^^^^^^^^^^
  File "/home/airflow/.local/lib/python3.12/site-packages/airflow/models/baseoperator.py", line 406, in wrapper
    return func(self, *args, **kwargs)
           ^^^^^^^^^^^^^^^^^^^^^^^^^^^
  File "/home/airflow/.local/lib/python3.12/site-packages/airflow/operators/python.py", line 238, in execute
    return_value = self.execute_callable()
                   ^^^^^^^^^^^^^^^^^^^^^^^
  File "/home/airflow/.local/lib/python3.12/site-packages/airflow/operators/python.py", line 256, in execute_callable
    return runner.run(*self.op_args, **self.op_kwargs)
           ^^^^^^^^^^^^^^^^^^^^^^^^^^^^^^^^^^^^^^^^^^^
  File "/home/airflow/.local/lib/python3.12/site-packages/airflow/utils/operator_helpers.py", line 252, in run
    return self.func(*args, **kwargs)
           ^^^^^^^^^^^^^^^^^^^^^^^^^^
  File "/opt/airflow/dags/logic/raw_fetch_sales_api.py", line 22, in fetch_sales_data
    raise ValueError(f"Error fetching data, status code: {response.status_code}")
ValueError: Error fetching data, status code: 404
[2024-11-03T04:09:01.974+0000] {logging_mixin.py:190} INFO - Task instance in failure state
[2024-11-03T04:09:01.975+0000] {logging_mixin.py:190} INFO - Task start:2024-11-03 04:09:00.937735+00:00 end:2024-11-03 04:09:01.974551+00:00 duration:1.036816
[2024-11-03T04:09:01.975+0000] {logging_mixin.py:190} INFO - Task:<Task(PythonOperator): fetch_sales_data_raw> dag:<DAG: load_sales_data_to_db> dagrun:<DagRun load_sales_data_to_db @ 2024-11-03 04:08:00+00:00: scheduled__2024-11-03T04:08:00+00:00, state:running, queued_at: 2024-11-03 04:09:00.271884+00:00. externally triggered: False>
[2024-11-03T04:09:01.975+0000] {logging_mixin.py:190} INFO - Failure caused by Error fetching data, status code: 404
[2024-11-03T04:09:01.975+0000] {taskinstance.py:1225} INFO - Marking task as UP_FOR_RETRY. dag_id=load_sales_data_to_db, task_id=fetch_sales_data_raw, run_id=scheduled__2024-11-03T04:08:00+00:00, execution_date=20241103T040800, start_date=20241103T040900, end_date=20241103T040901
[2024-11-03T04:09:01.986+0000] {taskinstance.py:340} INFO - ::group::Post task execution logs
[2024-11-03T04:09:01.987+0000] {standard_task_runner.py:124} ERROR - Failed to execute job 190 for task fetch_sales_data_raw (Error fetching data, status code: 404; 451)
Traceback (most recent call last):
  File "/home/airflow/.local/lib/python3.12/site-packages/airflow/task/task_runner/standard_task_runner.py", line 117, in _start_by_fork
    ret = args.func(args, dag=self.dag)
          ^^^^^^^^^^^^^^^^^^^^^^^^^^^^^
  File "/home/airflow/.local/lib/python3.12/site-packages/airflow/cli/cli_config.py", line 49, in command
    return func(*args, **kwargs)
           ^^^^^^^^^^^^^^^^^^^^^
  File "/home/airflow/.local/lib/python3.12/site-packages/airflow/utils/cli.py", line 115, in wrapper
    return f(*args, **kwargs)
           ^^^^^^^^^^^^^^^^^^
  File "/home/airflow/.local/lib/python3.12/site-packages/airflow/cli/commands/task_command.py", line 483, in task_run
    task_return_code = _run_task_by_selected_method(args, _dag, ti)
                       ^^^^^^^^^^^^^^^^^^^^^^^^^^^^^^^^^^^^^^^^^^^^
  File "/home/airflow/.local/lib/python3.12/site-packages/airflow/cli/commands/task_command.py", line 256, in _run_task_by_selected_method
    return _run_raw_task(args, ti)
           ^^^^^^^^^^^^^^^^^^^^^^^
  File "/home/airflow/.local/lib/python3.12/site-packages/airflow/cli/commands/task_command.py", line 341, in _run_raw_task
    return ti._run_raw_task(
           ^^^^^^^^^^^^^^^^^
  File "/home/airflow/.local/lib/python3.12/site-packages/airflow/utils/session.py", line 97, in wrapper
    return func(*args, session=session, **kwargs)
           ^^^^^^^^^^^^^^^^^^^^^^^^^^^^^^^^^^^^^^
  File "/home/airflow/.local/lib/python3.12/site-packages/airflow/models/taskinstance.py", line 3004, in _run_raw_task
    return _run_raw_task(
           ^^^^^^^^^^^^^^
  File "/home/airflow/.local/lib/python3.12/site-packages/airflow/models/taskinstance.py", line 273, in _run_raw_task
    TaskInstance._execute_task_with_callbacks(
  File "/home/airflow/.local/lib/python3.12/site-packages/airflow/models/taskinstance.py", line 3158, in _execute_task_with_callbacks
    result = self._execute_task(context, task_orig)
             ^^^^^^^^^^^^^^^^^^^^^^^^^^^^^^^^^^^^^^
  File "/home/airflow/.local/lib/python3.12/site-packages/airflow/models/taskinstance.py", line 3182, in _execute_task
    return _execute_task(self, context, task_orig)
           ^^^^^^^^^^^^^^^^^^^^^^^^^^^^^^^^^^^^^^^
  File "/home/airflow/.local/lib/python3.12/site-packages/airflow/models/taskinstance.py", line 767, in _execute_task
    result = _execute_callable(context=context, **execute_callable_kwargs)
             ^^^^^^^^^^^^^^^^^^^^^^^^^^^^^^^^^^^^^^^^^^^^^^^^^^^^^^^^^^^^^
  File "/home/airflow/.local/lib/python3.12/site-packages/airflow/models/taskinstance.py", line 733, in _execute_callable
    return ExecutionCallableRunner(
           ^^^^^^^^^^^^^^^^^^^^^^^^
  File "/home/airflow/.local/lib/python3.12/site-packages/airflow/utils/operator_helpers.py", line 252, in run
    return self.func(*args, **kwargs)
           ^^^^^^^^^^^^^^^^^^^^^^^^^^
  File "/home/airflow/.local/lib/python3.12/site-packages/airflow/models/baseoperator.py", line 406, in wrapper
    return func(self, *args, **kwargs)
           ^^^^^^^^^^^^^^^^^^^^^^^^^^^
  File "/home/airflow/.local/lib/python3.12/site-packages/airflow/operators/python.py", line 238, in execute
    return_value = self.execute_callable()
                   ^^^^^^^^^^^^^^^^^^^^^^^
  File "/home/airflow/.local/lib/python3.12/site-packages/airflow/operators/python.py", line 256, in execute_callable
    return runner.run(*self.op_args, **self.op_kwargs)
           ^^^^^^^^^^^^^^^^^^^^^^^^^^^^^^^^^^^^^^^^^^^
  File "/home/airflow/.local/lib/python3.12/site-packages/airflow/utils/operator_helpers.py", line 252, in run
    return self.func(*args, **kwargs)
           ^^^^^^^^^^^^^^^^^^^^^^^^^^
  File "/opt/airflow/dags/logic/raw_fetch_sales_api.py", line 22, in fetch_sales_data
    raise ValueError(f"Error fetching data, status code: {response.status_code}")
ValueError: Error fetching data, status code: 404
[2024-11-03T04:09:02.021+0000] {local_task_job_runner.py:266} INFO - Task exited with return code 1
[2024-11-03T04:09:02.033+0000] {taskinstance.py:3900} INFO - 0 downstream tasks scheduled from follow-on schedule check
[2024-11-03T04:09:02.034+0000] {local_task_job_runner.py:245} INFO - ::endgroup::
