[2024-11-03T02:47:03.634+0000] {local_task_job_runner.py:123} INFO - ::group::Pre task execution logs
[2024-11-03T02:47:03.641+0000] {taskinstance.py:2612} INFO - Dependencies all met for dep_context=non-requeueable deps ti=<TaskInstance: load_sales_data_to_db.store_sales_data_raw scheduled__2024-11-03T02:46:00+00:00 [queued]>
[2024-11-03T02:47:03.646+0000] {taskinstance.py:2612} INFO - Dependencies all met for dep_context=requeueable deps ti=<TaskInstance: load_sales_data_to_db.store_sales_data_raw scheduled__2024-11-03T02:46:00+00:00 [queued]>
[2024-11-03T02:47:03.647+0000] {taskinstance.py:2865} INFO - Starting attempt 1 of 2
[2024-11-03T02:47:03.653+0000] {taskinstance.py:2888} INFO - Executing <Task(PythonOperator): store_sales_data_raw> on 2024-11-03 02:46:00+00:00
[2024-11-03T02:47:03.656+0000] {warnings.py:112} WARNING - /home/***/.local/lib/python3.12/site-packages/***/task/task_runner/standard_task_runner.py:70: DeprecationWarning: This process (pid=3572) is multi-threaded, use of fork() may lead to deadlocks in the child.
  pid = os.fork()

[2024-11-03T02:47:03.657+0000] {standard_task_runner.py:72} INFO - Started process 3577 to run task
[2024-11-03T02:47:03.658+0000] {standard_task_runner.py:104} INFO - Running: ['***', 'tasks', 'run', 'load_sales_data_to_db', 'store_sales_data_raw', 'scheduled__2024-11-03T02:46:00+00:00', '--job-id', '360', '--raw', '--subdir', 'DAGS_FOLDER/raw/sales.py', '--cfg-path', '/tmp/tmpkdeqi5c0']
[2024-11-03T02:47:03.659+0000] {standard_task_runner.py:105} INFO - Job 360: Subtask store_sales_data_raw
[2024-11-03T02:47:03.687+0000] {task_command.py:467} INFO - Running <TaskInstance: load_sales_data_to_db.store_sales_data_raw scheduled__2024-11-03T02:46:00+00:00 [running]> on host f05559d9e656
[2024-11-03T02:47:03.727+0000] {taskinstance.py:3131} INFO - Exporting env vars: AIRFLOW_CTX_DAG_OWNER='***' AIRFLOW_CTX_DAG_ID='load_sales_data_to_db' AIRFLOW_CTX_TASK_ID='store_sales_data_raw' AIRFLOW_CTX_EXECUTION_DATE='2024-11-03T02:46:00+00:00' AIRFLOW_CTX_TRY_NUMBER='1' AIRFLOW_CTX_DAG_RUN_ID='scheduled__2024-11-03T02:46:00+00:00'
[2024-11-03T02:47:03.728+0000] {logging_mixin.py:190} INFO - Task instance is in running state
[2024-11-03T02:47:03.729+0000] {logging_mixin.py:190} INFO -  Previous state of the Task instance: queued
[2024-11-03T02:47:03.729+0000] {logging_mixin.py:190} INFO - Current task name:store_sales_data_raw state:running start_date:2024-11-03 02:47:03.642147+00:00
[2024-11-03T02:47:03.729+0000] {logging_mixin.py:190} INFO - Dag name:load_sales_data_to_db and current dag run status:running
[2024-11-03T02:47:03.730+0000] {taskinstance.py:731} INFO - ::endgroup::
[2024-11-03T02:47:03.744+0000] {taskinstance.py:3310} ERROR - Task failed with exception
Traceback (most recent call last):
  File "/home/airflow/.local/lib/python3.12/site-packages/airflow/models/taskinstance.py", line 767, in _execute_task
    result = _execute_callable(context=context, **execute_callable_kwargs)
             ^^^^^^^^^^^^^^^^^^^^^^^^^^^^^^^^^^^^^^^^^^^^^^^^^^^^^^^^^^^^^
  File "/home/airflow/.local/lib/python3.12/site-packages/airflow/models/taskinstance.py", line 733, in _execute_callable
    return ExecutionCallableRunner(
           ^^^^^^^^^^^^^^^^^^^^^^^^
  File "/home/airflow/.local/lib/python3.12/site-packages/airflow/utils/operator_helpers.py", line 252, in run
    return self.func(*args, **kwargs)
           ^^^^^^^^^^^^^^^^^^^^^^^^^^
  File "/home/airflow/.local/lib/python3.12/site-packages/airflow/models/baseoperator.py", line 406, in wrapper
    return func(self, *args, **kwargs)
           ^^^^^^^^^^^^^^^^^^^^^^^^^^^
  File "/home/airflow/.local/lib/python3.12/site-packages/airflow/operators/python.py", line 238, in execute
    return_value = self.execute_callable()
                   ^^^^^^^^^^^^^^^^^^^^^^^
  File "/home/airflow/.local/lib/python3.12/site-packages/airflow/operators/python.py", line 256, in execute_callable
    return runner.run(*self.op_args, **self.op_kwargs)
           ^^^^^^^^^^^^^^^^^^^^^^^^^^^^^^^^^^^^^^^^^^^
  File "/home/airflow/.local/lib/python3.12/site-packages/airflow/utils/operator_helpers.py", line 252, in run
    return self.func(*args, **kwargs)
           ^^^^^^^^^^^^^^^^^^^^^^^^^^
  File "/opt/airflow/dags/raw/sales.py", line 63, in store_sales_data_to_db
    conn = duckdb.connect(duckdb_path)
           ^^^^^^^^^^^^^^^^^^^^^^^^^^^
duckdb.duckdb.IOException: IO Error: Cannot open file "/opt/***/db/ecommerce_data.db": No such file or directory
[2024-11-03T02:47:03.753+0000] {logging_mixin.py:190} INFO - Task instance in failure state
[2024-11-03T02:47:03.754+0000] {logging_mixin.py:190} INFO - Task start:2024-11-03 02:47:03.642147+00:00 end:2024-11-03 02:47:03.753698+00:00 duration:0.111551
[2024-11-03T02:47:03.754+0000] {logging_mixin.py:190} INFO - Task:<Task(PythonOperator): store_sales_data_raw> dag:<DAG: load_sales_data_to_db> dagrun:<DagRun load_sales_data_to_db @ 2024-11-03 02:46:00+00:00: scheduled__2024-11-03T02:46:00+00:00, state:running, queued_at: 2024-11-03 02:47:00.769032+00:00. externally triggered: False>
[2024-11-03T02:47:03.754+0000] {logging_mixin.py:190} INFO - Failure caused by IO Error: Cannot open file "/opt/***/db/ecommerce_data.db": No such file or directory
[2024-11-03T02:47:03.755+0000] {taskinstance.py:1225} INFO - Marking task as UP_FOR_RETRY. dag_id=load_sales_data_to_db, task_id=store_sales_data_raw, run_id=scheduled__2024-11-03T02:46:00+00:00, execution_date=20241103T024600, start_date=20241103T024703, end_date=20241103T024703
[2024-11-03T02:47:03.762+0000] {taskinstance.py:340} INFO - ::group::Post task execution logs
[2024-11-03T02:47:03.762+0000] {standard_task_runner.py:124} ERROR - Failed to execute job 360 for task store_sales_data_raw (IO Error: Cannot open file "/opt/***/db/ecommerce_data.db": No such file or directory; 3577)
Traceback (most recent call last):
  File "/home/airflow/.local/lib/python3.12/site-packages/airflow/task/task_runner/standard_task_runner.py", line 117, in _start_by_fork
    ret = args.func(args, dag=self.dag)
          ^^^^^^^^^^^^^^^^^^^^^^^^^^^^^
  File "/home/airflow/.local/lib/python3.12/site-packages/airflow/cli/cli_config.py", line 49, in command
    return func(*args, **kwargs)
           ^^^^^^^^^^^^^^^^^^^^^
  File "/home/airflow/.local/lib/python3.12/site-packages/airflow/utils/cli.py", line 115, in wrapper
    return f(*args, **kwargs)
           ^^^^^^^^^^^^^^^^^^
  File "/home/airflow/.local/lib/python3.12/site-packages/airflow/cli/commands/task_command.py", line 483, in task_run
    task_return_code = _run_task_by_selected_method(args, _dag, ti)
                       ^^^^^^^^^^^^^^^^^^^^^^^^^^^^^^^^^^^^^^^^^^^^
  File "/home/airflow/.local/lib/python3.12/site-packages/airflow/cli/commands/task_command.py", line 256, in _run_task_by_selected_method
    return _run_raw_task(args, ti)
           ^^^^^^^^^^^^^^^^^^^^^^^
  File "/home/airflow/.local/lib/python3.12/site-packages/airflow/cli/commands/task_command.py", line 341, in _run_raw_task
    return ti._run_raw_task(
           ^^^^^^^^^^^^^^^^^
  File "/home/airflow/.local/lib/python3.12/site-packages/airflow/utils/session.py", line 97, in wrapper
    return func(*args, session=session, **kwargs)
           ^^^^^^^^^^^^^^^^^^^^^^^^^^^^^^^^^^^^^^
  File "/home/airflow/.local/lib/python3.12/site-packages/airflow/models/taskinstance.py", line 3004, in _run_raw_task
    return _run_raw_task(
           ^^^^^^^^^^^^^^
  File "/home/airflow/.local/lib/python3.12/site-packages/airflow/models/taskinstance.py", line 273, in _run_raw_task
    TaskInstance._execute_task_with_callbacks(
  File "/home/airflow/.local/lib/python3.12/site-packages/airflow/models/taskinstance.py", line 3158, in _execute_task_with_callbacks
    result = self._execute_task(context, task_orig)
             ^^^^^^^^^^^^^^^^^^^^^^^^^^^^^^^^^^^^^^
  File "/home/airflow/.local/lib/python3.12/site-packages/airflow/models/taskinstance.py", line 3182, in _execute_task
    return _execute_task(self, context, task_orig)
           ^^^^^^^^^^^^^^^^^^^^^^^^^^^^^^^^^^^^^^^
  File "/home/airflow/.local/lib/python3.12/site-packages/airflow/models/taskinstance.py", line 767, in _execute_task
    result = _execute_callable(context=context, **execute_callable_kwargs)
             ^^^^^^^^^^^^^^^^^^^^^^^^^^^^^^^^^^^^^^^^^^^^^^^^^^^^^^^^^^^^^
  File "/home/airflow/.local/lib/python3.12/site-packages/airflow/models/taskinstance.py", line 733, in _execute_callable
    return ExecutionCallableRunner(
           ^^^^^^^^^^^^^^^^^^^^^^^^
  File "/home/airflow/.local/lib/python3.12/site-packages/airflow/utils/operator_helpers.py", line 252, in run
    return self.func(*args, **kwargs)
           ^^^^^^^^^^^^^^^^^^^^^^^^^^
  File "/home/airflow/.local/lib/python3.12/site-packages/airflow/models/baseoperator.py", line 406, in wrapper
    return func(self, *args, **kwargs)
           ^^^^^^^^^^^^^^^^^^^^^^^^^^^
  File "/home/airflow/.local/lib/python3.12/site-packages/airflow/operators/python.py", line 238, in execute
    return_value = self.execute_callable()
                   ^^^^^^^^^^^^^^^^^^^^^^^
  File "/home/airflow/.local/lib/python3.12/site-packages/airflow/operators/python.py", line 256, in execute_callable
    return runner.run(*self.op_args, **self.op_kwargs)
           ^^^^^^^^^^^^^^^^^^^^^^^^^^^^^^^^^^^^^^^^^^^
  File "/home/airflow/.local/lib/python3.12/site-packages/airflow/utils/operator_helpers.py", line 252, in run
    return self.func(*args, **kwargs)
           ^^^^^^^^^^^^^^^^^^^^^^^^^^
  File "/opt/airflow/dags/raw/sales.py", line 63, in store_sales_data_to_db
    conn = duckdb.connect(duckdb_path)
           ^^^^^^^^^^^^^^^^^^^^^^^^^^^
duckdb.duckdb.IOException: IO Error: Cannot open file "/opt/***/db/ecommerce_data.db": No such file or directory
[2024-11-03T02:47:03.791+0000] {local_task_job_runner.py:266} INFO - Task exited with return code 1
[2024-11-03T02:47:03.800+0000] {taskinstance.py:3900} INFO - 0 downstream tasks scheduled from follow-on schedule check
[2024-11-03T02:47:03.802+0000] {local_task_job_runner.py:245} INFO - ::endgroup::
